Workbook

Sheet DISPO Att (2)
A1: Republic of the Philippines
A2: PHILIPPINE NATIONAL POLICE | J2: =259-240 -> 19
A3: INFORMATION TECHNOLOGY MANAGEMENT SERVICE | J3: =134-63 -> 71
A4: Camp Bgen Rafael T Crame, Quezon City
A6: Disposition of Personnel (Crame-Based Only)
A7: (As of January 22, 2026)
A9: NO. | B9: OFFICE/DIVISION | C9: GENDER | D9: RANK | E9: LASTNAME | F9: FIRSTNAME | G9: MIDDLE NAME | H9: QUAL | I9: SIGNATURE | J9: ADDRESS | K9: CONTACT # | P9: NAME | Q9: ADDRESS
A10: 1 | B10: OD | C10: Male | D10: PCOL | E10: PALGUE | F10: ROMY | G10: INWAY
A11: 2 | B11: OD | C11: Male | D11: PCpl | E11: CERIL | F11: PAUL KELVIN | G11: LAROZA
A12: 3 | B12: OD | C12: Male | D12: Pat | E12: BEJARIN | F12: GERALD | G12: DADIRO | J12: Riang, Peñarrubia, Abra | K12: 09368167960 | P12: =CONCATENATE(E12," ",F12," ",G12) -> BEJARIN GERALD DADIRO | Q12: =IFERROR(VLOOKUP(P12,[1]Disposition!$AB$9:$AC$495,2,0),"NO RECORD YET") -> NO RECORD YET
A13: 4 | B13: OD | C13: Male | D13: Pat | E13: MORI | F13: LYNDON | G13: ACOSTA | J13: Caimito, Brgy. Buencag, Gerona, Tarlac | K13: 09091819560 | P13: =CONCATENATE(E13," ",F13," ",G13) -> MORI LYNDON ACOSTA | Q13: =IFERROR(VLOOKUP(P13,[1]Disposition!$AB$9:$AC$495,2,0),"NO RECORD YET") -> NO RECORD YET
A14: 5 | B14: OD | C14: Female | D14: NUP | E14: AVENDAÑO | F14: MA. FRELIE JOY | G14: (no middle name) | J14: #92 F Estrella St., San Juan, Malolos City, Bulacan | K14: 09554289264 | P14: =CONCATENATE(E14," ",F14," ",G14) -> AVENDAÑO MA. FRELIE JOY (no middle name) | Q14: =IFERROR(VLOOKUP(P14,[1]Disposition!$AB$9:$AC$495,2,0),"NO RECORD YET") -> #92 F Estrella St., San Juan, Malolos City, Bulacan
A15: 6 | B15: OD | C15: Female | D15: NUP | E15: LUZARA | F15: JEAN | G15: GRATUITO | J15: Blk 5 Lot 1 Orchid Extension, Capitol Park Homes Ii, Brgy 179 Zone 16, Caloocan City. | K15: 09177037934 | M15: 25 | P15: =CONCATENATE(E15," ",F15," ",G15) -> LUZARA JEAN GRATUITO | Q15: =IFERROR(VLOOKUP(P15,[1]Disposition!$AB$9:$AC$495,2,0),"NO RECORD YET") -> Blk 5 Lot 1 Orchid Extension, Capitol Park Homes II, Brgy 179 Zone 16, Caloocan City.
A16: 7 | B16: ODDA/DI | C16: Male | D16: PCOL | E16: TANGO | F16: FROILAN GENN | G16: GELACIO | H16: II | M16: 259 | P16: =CONCATENATE(E16," ",F16," ",G16) -> TANGO FROILAN GENN GELACIO
A17: 8 | B17: ODDA | C17: Male | D17: PMSg | E17: RESPICIO | F17: VIC BASKAR | G17: MADDARA | J17: Calamagui 2Nd, Isabela | K17: 09268096361 | M17: 134 | P17: =CONCATENATE(E17," ",F17," ",G17) -> RESPICIO VIC BASKAR MADDARA | Q17: =IFERROR(VLOOKUP(P17,[1]Disposition!$AB$9:$AC$495,2,0),"NO RECORD YET") -> Calamagui 2nd, Isabela
A18: 9 | B18: ODDA | C18: Female | D18: NUP | E18: ERIBAL | F18: JOZEL JOY | G18: FALAGNE | J18: 5A Diamond St., Jra Subd., Rosario, Pasug City | K18: 09617215961 | M18: 41 | P18: =CONCATENATE(E18," ",F18," ",G18) -> ERIBAL JOZEL JOY FALAGNE | Q18: =IFERROR(VLOOKUP(P18,[1]Disposition!$AB$9:$AC$495,2,0),"NO RECORD YET") -> 5A Diamond St., JRA Subd., Rosario, Pasug City
A19: 10 | B19: ODDA | C19: Female | D19: NUP | E19: SEMILLA | F19: FLORITES | G19: SARIO | J19: 18 C Dungo St., Brgy, Isabelita, San Juan City | K19: 09274390528 | M19: 40 | P19: =CONCATENATE(E19," ",F19," ",G19) -> SEMILLA FLORITES SARIO
A20: 11 | B20: DD for IT Matters | C20: Female | D20: NUP | E20: MATILLANO | F20: MINA HAYDEE | G20: BECERA | J20: B2 L17 Rose St., Venice Homes Subd., Cainta, Rizal | K20: 09266411836 | M20: 20 | P20: =CONCATENATE(E20," ",F20," ",G20) -> MATILLANO MINA HAYDEE BECERA | Q20: =IFERROR(VLOOKUP(P20,[1]Disposition!$AB$9:$AC$495,2,0),"NO RECORD YET") -> B2 L17 Rose St., Venice Homes Subd., Cainta, Rizal
A21: 12 | B21: ODDIT | C21: Female | D21: Pat | E21: PAPA | F21: MARIZ NICOLE | G21: ENGALAN | J21: 8H Road 6, 1st West Crame, San Juan City | K21: 09563393345 | M21: 30 | P21: =CONCATENATE(E21," ",F21," ",G21) -> PAPA MARIZ NICOLE ENGALAN | Q21: =IFERROR(VLOOKUP(P21,[1]Disposition!$AB$9:$AC$495,2,0),"NO RECORD YET") -> NO RECORD YET
A22: 13 | B22: ODDIT | C22: Female | D22: NUP | E22: BAGO | F22: REBECCA | G22: LLANEZA | J22: 196 Guyam Malaki, Indang, Cavite | K22: 09278398862 | M22: 17 | P22: =CONCATENATE(E22," ",F22," ",G22) -> BAGO REBECCA LLANEZA | Q22: =IFERROR(VLOOKUP(P22,[1]Disposition!$AB$9:$AC$495,2,0),"NO RECORD YET") -> 196 Guyam Malaki, Indang, Cavite
A23: 14 | B23: OCS | C23: Male | D23: PCOL | E23: PATIÑO | F23: RANDI | G23: MANZANO | J23: Mddle Nivel Hills, Brgy Apas, Cebu City | K23: 09057369133 | P23: =CONCATENATE(E23," ",F23," ",G23) -> PATIÑO RANDI MANZANO | Q23: =IFERROR(VLOOKUP(P23,[1]Disposition!$AB$9:$AC$495,2,0),"NO RECORD YET") -> Mddle Nivel Hills, Brgy Apas, Cebu City
A24: 15 | B24: OCS | C24: Male | D24: PCPT | E24: KARIM | F24: BENSAR ALI | G24: ABDULGANI | J24: 21-B Maguindanao St, Culiat, Quezon City | K24: 09267388655 | P24: =CONCATENATE(E24," ",F24," ",G24) -> KARIM BENSAR ALI ABDULGANI | Q24: =IFERROR(VLOOKUP(P24,[1]Disposition!$AB$9:$AC$495,2,0),"NO RECORD YET") -> 21-B Maguindanao St, Culiat, Quezon City
A25: 16 | B25: OCS | C25: Male | D25: PCpl | E25: AGGARAO | F25: ALBERTO | G25: CALLANGAN | J25: 215 D Guiho St., Cembo, Makati City | K25: 09434383476 | M25: =SUM(M15:M24) -> 566 | P25: =CONCATENATE(E25," ",F25," ",G25) -> AGGARAO ALBERTO CALLANGAN | Q25: =IFERROR(VLOOKUP(P25,[1]Disposition!$AB$9:$AC$495,2,0),"NO RECORD YET") -> 215 D Guiho St., Cembo, Makati City
A26: 17 | B26: OCS | C26: Female | D26: PCpl | E26: SANG-AN | F26: CATHERINE | G26: VALDESTAMON | J26: Zone 1 Purok Maligaya, Tagburos, Puerto Princesa City, Palawan | K26: 09279979400 | P26: =CONCATENATE(E26," ",F26," ",G26) -> SANG-AN CATHERINE VALDESTAMON | Q26: =IFERROR(VLOOKUP(P26,[1]Disposition!$AB$9:$AC$495,2,0),"NO RECORD YET") -> NO RECORD YET
A27: 18 | B27: OCS | C27: Female | D27: NUP | E27: ESTEVES | F27: MARICEL | G27: FRESNOZA | J27: 3310 Bataan St., Bacood, Sta.Mesa, Manila | K27: 09293473925 | M27: =205-146 -> 59 | P27: =CONCATENATE(E27," ",F27," ",G27) -> ESTEVES MARICEL FRESNOZA | Q27: =IFERROR(VLOOKUP(P27,[1]Disposition!$AB$9:$AC$495,2,0),"NO RECORD YET") -> 3310 Bataan St., Bacood, Sta.Mesa, Manila
A28: 19 | B28: OCS | C28: Male | D28: NUP | E28: NADORA | F28: ADRIAN JOSE | G28: POSADAS | J28: 16 Maligaya St., Rosario 6 Subd, Sta Lucia, Pasig City 1608 | K28: 09179713272 | P28: =CONCATENATE(E28," ",F28," ",G28) -> NADORA ADRIAN JOSE POSADAS | Q28: =IFERROR(VLOOKUP(P28,[1]Disposition!$AB$9:$AC$495,2,0),"NO RECORD YET") -> 16 Maligaya St., Rosario 6 Subd, Sta Lucia, Pasig City 1608
A29: 20 | B29: PIO | C29: Male | D29: Pat | E29: PEÑON | F29: JAYSON | G29: CABRAL | J29: 1901 Interior, Zamora Street, Manila, NCR | K29: 09608411365 | P29: =CONCATENATE(E29," ",F29," ",G29) -> PEÑON JAYSON CABRAL | Q29: =IFERROR(VLOOKUP(P29,[1]Disposition!$AB$9:$AC$495,2,0),"NO RECORD YET") -> NO RECORD YET
A30: 21 | B30: PIO | C30: Female | D30: NUP | E30: ALVAREZ | F30: PAMELA | G30: CEREZO | J30: Pao, Manaoag, Pangasinan | K30: 09615765167 | P30: =CONCATENATE(E30," ",F30," ",G30) -> ALVAREZ PAMELA CEREZO | Q30: =IFERROR(VLOOKUP(P30,[1]Disposition!$AB$9:$AC$495,2,0),"NO RECORD YET") -> Pao, Manaoag, Pangasinan
A31: 22 | B31: PIO | C31: Male | D31: NUP | E31: RUIVIVAR | F31: JOSE SALVADOR | G31: DEL ROSARIO | J31: 13 St. Joseph St., Milton Hills Subd, Diliman, Quezon City | K31: 09770330570 | P31: =CONCATENATE(E31," ",F31," ",G31) -> RUIVIVAR JOSE SALVADOR DEL ROSARIO | Q31: =IFERROR(VLOOKUP(P31,[1]Disposition!$AB$9:$AC$495,2,0),"NO RECORD YET") -> 13 St. Joseph St., Milton Hills Subd, Diliman, Quezon City
A32: 23 | B32: SLO/OCI | C32: Female | D32: PCpl | E32: CUASAY | F32: ZAYRA JANE | G32: CEDENO | J32: 29 P Dizon Circle, Hen. T. De Leon, Valenzuela City | K32: 09953744137 | P32: =CONCATENATE(E32," ",F32," ",G32) -> CUASAY ZAYRA JANE CEDENO | Q32: =IFERROR(VLOOKUP(P32,[1]Disposition!$AB$9:$AC$495,2,0),"NO RECORD YET") -> NO RECORD YET
A33: 24 | B33: SLO/OCI | C33: Female | D33: NUP | E33: COSTALES | F33: MARY GRACE | G33: RODRIGUEZ | J33: 7C 2Nd Ave., Bagong Lipunan Ng Crame, Quezon City | K33: 09275492985 | P33: =CONCATENATE(E33," ",F33," ",G33) -> COSTALES MARY GRACE RODRIGUEZ | Q33: =IFERROR(VLOOKUP(P33,[1]Disposition!$AB$9:$AC$495,2,0),"NO RECORD YET") -> NO RECORD YET
A34: 25 | B34: SLO/OCI | C34: Female | D34: NUP | E34: VER | F34: MARIE LOUISE ROVIAN | G34: RAMOS | J34: Blk 43 Lot 16, Phase 7, Eastwood Residences, Brgy San Isidro, Montalban, Rizal | K34: 09158167417 | M34: =177-226 -> -49 | P34: =CONCATENATE(E34," ",F34," ",G34) -> VER MARIE LOUISE ROVIAN RAMOS | Q34: =IFERROR(VLOOKUP(P34,[1]Disposition!$AB$9:$AC$495,2,0),"NO RECORD YET") -> Blk 43 Lot 16, Phase 7, Eastwood Residences, Brgy San Isidro, Montalban, Rizal
A35: 26 | B35: ITPMD | C35: Male | D35: PCOL | E35: BORRES | F35: RUBEN | G35: BROSAS | J35: 163-W 20Th Avenue, Rembo, Makati City | K35: 09367450777 | P35: =CONCATENATE(E35," ",F35," ",G35) -> BORRES RUBEN BROSAS | Q35: =IFERROR(VLOOKUP(P35,[1]Disposition!$AB$9:$AC$495,2,0),"NO RECORD YET") -> NO RECORD YET
A36: 27 | B36: ITPMD | C36: Female | D36: PLTCOL | E36: FABRO | F36: JHOANA GRACIA | G36: MANLAPAZ
A37: 28 | B37: ITPMD | C37: Female | D37: NUP | E37: GONZALES | F37: NECILDA | G37: JAVINIAR | J37: 641 Blk 22 Kabisig Floodway, San Andres, Cainta, Rizal | K37: 09187708759 | P37: =CONCATENATE(E200," ",F200," ",G200) -> BATICADOS IVY ELEGARLE | Q37: =IFERROR(VLOOKUP(P37,[1]Disposition!$AB$9:$AC$495,2,0),"NO RECORD YET") -> EL Dorado Dulo, Brgy. Don Bosco, Better Living Subd., Parañaque City
A38: 29 | B38: ITPMIS, ITPMD | C38: Female | D38: PCPT | E38: QUINTOS | F38: ANGELICA | G38: AGOR | J38: B1 L128 Phase 1F, Sub Urban Village, San Jose, Montalban, Rizal | K38: 09458154169 | P38: =CONCATENATE(E38," ",F38," ",G38) -> QUINTOS ANGELICA AGOR | Q38: =IFERROR(VLOOKUP(P38,[1]Disposition!$AB$9:$AC$495,2,0),"NO RECORD YET") -> B1 L128 Phase 1F, Sub Urban Village, San Jose, Montalban, Rizal
A39: 30 | B39: ITPMIS, ITPMD | C39: Female | D39: Pat | E39: CELARIO | F39: RUBY ROSE | G39: BUEZA | J39: 37 Tagumpay St. Marawi, Camiling, Tarlac | K39: 09514992446 | N39: =566-554 -> 12 | P39: =CONCATENATE(E39," ",F39," ",G39) -> CELARIO RUBY ROSE BUEZA | Q39: =IFERROR(VLOOKUP(P39,[1]Disposition!$AB$9:$AC$495,2,0),"NO RECORD YET") -> NO RECORD YET
A40: 31 | B40: ITPMIS, ITPMD | C40: Male | D40: Pat | E40: MANAOG | F40: RODNIE | G40: CASTILLO | J40: Sitio Pongol., Brgy. Burabod, San Antonio, Northern Samar | K40: 09452066435 | N40: 3 | P40: =CONCATENATE(E40," ",F40," ",G40) -> MANAOG RODNIE CASTILLO | Q40: =IFERROR(VLOOKUP(P40,[1]Disposition!$AB$9:$AC$495,2,0),"NO RECORD YET") -> NO RECORD YET
A41: 32 | B41: ITPMIS, ITPMD | C41: Male | D41: NUP | E41: DAGTA | F41: MARY ANN | G41: YAP | J41: Blk 3, Lot 20, Amber St., Summit Viwe Subd., Brgy. San Rafael, Rodriguez, Rizal | K41: 09568629227 | P41: =CONCATENATE(E41," ",F41," ",G41) -> DAGTA MARY ANN YAP | Q41: =IFERROR(VLOOKUP(P41,[1]Disposition!$AB$9:$AC$495,2,0),"NO RECORD YET") -> Blk 3, Lot 20, Amber St., Summit Viwe Subd., Brgy. San Rafael, Rodriguez, Rizal
A42: 33 | B42: EMS, ITPMD | C42: Male | D42: PMSg | E42: PEÑAVERDE | F42: PHILIP JAMES | G42: RODRIGUEZ | J42: Blk 1 Lot 128 P1-F Sub-Urban Village, Saan Jose, Rodriguez, Rizal | K42: 09266167584 | P42: =CONCATENATE(E42," ",F42," ",G42) -> PEÑAVERDE PHILIP JAMES RODRIGUEZ | Q42: =IFERROR(VLOOKUP(P42,[1]Disposition!$AB$9:$AC$495,2,0),"NO RECORD YET") -> Blk 1 Lot 128 P1-F Sub-Urban Village, Saan Jose, Rodriguez, Rizal
...

Sheet DISPO Att
A1: Republic of the Philippines
A2: PHILIPPINE NATIONAL POLICE | J2: =259-240 -> 19
A3: INFORMATION TECHNOLOGY MANAGEMENT SERVICE | J3: =134-63 -> 71
A4: Camp Bgen Rafael T Crame, Quezon City
A6: Disposition of Personnel
A7: (As of January 22, 2026)
A9: NO. | B9: OFFICE/DIVISION | C9: GENDER | D9: RANK | E9: LASTNAME | F9: FIRSTNAME | G9: MIDDLE NAME | H9: QUAL | I9: SIGNATURE | J9: ADDRESS | K9: CONTACT # | P9: NAME | Q9: ADDRESS
A10: 1 | B10: OD | C10: Male | D10: PCOL | E10: PALGUE | F10: ROMY | G10: INWAY
A11: 2 | B11: OD | C11: Male | D11: PCpl | E11: CERIL | F11: PAUL KELVIN | G11: LAROZA
A12: 3 | B12: OD | C12: Male | D12: Pat | E12: BEJARIN | F12: GERALD | G12: DADIRO | J12: Riang, Peñarrubia, Abra | K12: 09368167960 | P12: =CONCATENATE(E12," ",F12," ",G12) -> BEJARIN GERALD DADIRO | Q12: =IFERROR(VLOOKUP(P12,[1]Disposition!$AB$9:$AC$495,2,0),"NO RECORD YET") -> NO RECORD YET
A13: 4 | B13: OD | C13: Male | D13: Pat | E13: MORI | F13: LYNDON | G13: ACOSTA | J13: Caimito, Brgy. Buencag, Gerona, Tarlac | K13: 09091819560 | P13: =CONCATENATE(E13," ",F13," ",G13) -> MORI LYNDON ACOSTA | Q13: =IFERROR(VLOOKUP(P13,[1]Disposition!$AB$9:$AC$495,2,0),"NO RECORD YET") -> NO RECORD YET
A14: 5 | B14: OD | C14: Female | D14: NUP | E14: AVENDAÑO | F14: MA. FRELIE JOY | G14: (no middle name) | J14: #92 F Estrella St., San Juan, Malolos City, Bulacan | K14: 09554289264 | P14: =CONCATENATE(E14," ",F14," ",G14) -> AVENDAÑO MA. FRELIE JOY (no middle name) | Q14: =IFERROR(VLOOKUP(P14,[1]Disposition!$AB$9:$AC$495,2,0),"NO RECORD YET") -> #92 F Estrella St., San Juan, Malolos City, Bulacan
A15: 7 | B15: OD | C15: Female | D15: NUP | E15: LUZARA | F15: JEAN | G15: GRATUITO | J15: Blk 5 Lot 1 Orchid Extension, Capitol Park Homes Ii, Brgy 179 Zone 16, Caloocan City. | K15: 09177037934 | M15: 25 | P15: =CONCATENATE(E15," ",F15," ",G15) -> LUZARA JEAN GRATUITO | Q15: =IFERROR(VLOOKUP(P15,[1]Disposition!$AB$9:$AC$495,2,0),"NO RECORD YET") -> Blk 5 Lot 1 Orchid Extension, Capitol Park Homes II, Brgy 179 Zone 16, Caloocan City.
A16: 8 | B16: ODDA/DI | C16: Male | D16: PCOL | E16: TANGO | F16: FROILAN GENN | G16: GELACIO | H16: II | M16: 259 | P16: =CONCATENATE(E16," ",F16," ",G16) -> TANGO FROILAN GENN GELACIO
A17: 9 | B17: ODDA | C17: Male | D17: PMSg | E17: RESPICIO | F17: VIC BASKAR | G17: MADDARA | J17: Calamagui 2Nd, Isabela | K17: 09268096361 | M17: 134 | P17: =CONCATENATE(E17," ",F17," ",G17) -> RESPICIO VIC BASKAR MADDARA | Q17: =IFERROR(VLOOKUP(P17,[1]Disposition!$AB$9:$AC$495,2,0),"NO RECORD YET") -> Calamagui 2nd, Isabela
A18: 10 | B18: ODDA | C18: Female | D18: NUP | E18: ERIBAL | F18: JOZEL JOY | G18: FALAGNE | J18: 5A Diamond St., Jra Subd., Rosario, Pasug City | K18: 09617215961 | M18: 41 | P18: =CONCATENATE(E18," ",F18," ",G18) -> ERIBAL JOZEL JOY FALAGNE | Q18: =IFERROR(VLOOKUP(P18,[1]Disposition!$AB$9:$AC$495,2,0),"NO RECORD YET") -> 5A Diamond St., JRA Subd., Rosario, Pasug City
A19: 11 | B19: ODDA | C19: Female | D19: NUP | E19: SEMILLA | F19: FLORITES | G19: SARIO | J19: 18 C Dungo St., Brgy, Isabelita, San Juan City | K19: 09274390528 | M19: 40 | P19: =CONCATENATE(E19," ",F19," ",G19) -> SEMILLA FLORITES SARIO
A20: 12 | B20: DD for IT Matters | C20: Female | D20: NUP | E20: MATILLANO | F20: MINA HAYDEE | G20: BECERA | J20: B2 L17 Rose St., Venice Homes Subd., Cainta, Rizal | K20: 09266411836 | M20: 20 | P20: =CONCATENATE(E20," ",F20," ",G20) -> MATILLANO MINA HAYDEE BECERA | Q20: =IFERROR(VLOOKUP(P20,[1]Disposition!$AB$9:$AC$495,2,0),"NO RECORD YET") -> B2 L17 Rose St., Venice Homes Subd., Cainta, Rizal
A21: 13 | B21: ODDIT | C21: Female | D21: Pat | E21: PAPA | F21: MARIZ NICOLE | G21: ENGALAN | J21: 8H Road 6, 1st West Crame, San Juan City | K21: 09563393345 | M21: 30 | P21: =CONCATENATE(E21," ",F21," ",G21) -> PAPA MARIZ NICOLE ENGALAN | Q21: =IFERROR(VLOOKUP(P21,[1]Disposition!$AB$9:$AC$495,2,0),"NO RECORD YET") -> NO RECORD YET
A22: 14 | B22: ODDIT | C22: Female | D22: NUP | E22: BAGO | F22: REBECCA | G22: LLANEZA | J22: 196 Guyam Malaki, Indang, Cavite | K22: 09278398862 | M22: 17 | P22: =CONCATENATE(E22," ",F22," ",G22) -> BAGO REBECCA LLANEZA | Q22: =IFERROR(VLOOKUP(P22,[1]Disposition!$AB$9:$AC$495,2,0),"NO RECORD YET") -> 196 Guyam Malaki, Indang, Cavite
A23: 15 | B23: OCS | C23: Male | D23: PCOL | E23: PATIÑO | F23: RANDI | G23: MANZANO | J23: Mddle Nivel Hills, Brgy Apas, Cebu City | K23: 09057369133 | P23: =CONCATENATE(E23," ",F23," ",G23) -> PATIÑO RANDI MANZANO | Q23: =IFERROR(VLOOKUP(P23,[1]Disposition!$AB$9:$AC$495,2,0),"NO RECORD YET") -> Mddle Nivel Hills, Brgy Apas, Cebu City
A24: 16 | B24: OCS | C24: Male | D24: PCPT | E24: KARIM | F24: BENSAR ALI | G24: ABDULGANI | J24: 21-B Maguindanao St, Culiat, Quezon City | K24: 09267388655 | P24: =CONCATENATE(E24," ",F24," ",G24) -> KARIM BENSAR ALI ABDULGANI | Q24: =IFERROR(VLOOKUP(P24,[1]Disposition!$AB$9:$AC$495,2,0),"NO RECORD YET") -> 21-B Maguindanao St, Culiat, Quezon City
A25: 17 | B25: OCS | C25: Male | D25: PCpl | E25: AGGARAO | F25: ALBERTO | G25: CALLANGAN | J25: 215 D Guiho St., Cembo, Makati City | K25: 09434383476 | M25: =SUM(M15:M24) -> 566 | P25: =CONCATENATE(E25," ",F25," ",G25) -> AGGARAO ALBERTO CALLANGAN | Q25: =IFERROR(VLOOKUP(P25,[1]Disposition!$AB$9:$AC$495,2,0),"NO RECORD YET") -> 215 D Guiho St., Cembo, Makati City
A26: 18 | B26: OCS | C26: Female | D26: PCpl | E26: SANG-AN | F26: CATHERINE | G26: VALDESTAMON | J26: Zone 1 Purok Maligaya, Tagburos, Puerto Princesa City, Palawan | K26: 09279979400 | P26: =CONCATENATE(E26," ",F26," ",G26) -> SANG-AN CATHERINE VALDESTAMON | Q26: =IFERROR(VLOOKUP(P26,[1]Disposition!$AB$9:$AC$495,2,0),"NO RECORD YET") -> NO RECORD YET
A27: 19 | B27: OCS | C27: Female | D27: NUP | E27: ESTEVES | F27: MARICEL | G27: FRESNOZA | J27: 3310 Bataan St., Bacood, Sta.Mesa, Manila | K27: 09293473925 | M27: =205-146 -> 59 | P27: =CONCATENATE(E27," ",F27," ",G27) -> ESTEVES MARICEL FRESNOZA | Q27: =IFERROR(VLOOKUP(P27,[1]Disposition!$AB$9:$AC$495,2,0),"NO RECORD YET") -> 3310 Bataan St., Bacood, Sta.Mesa, Manila
A28: 20 | B28: OCS | C28: Male | D28: NUP | E28: NADORA | F28: ADRIAN JOSE | G28: POSADAS | J28: 16 Maligaya St., Rosario 6 Subd, Sta Lucia, Pasig City 1608 | K28: 09179713272 | P28: =CONCATENATE(E28," ",F28," ",G28) -> NADORA ADRIAN JOSE POSADAS | Q28: =IFERROR(VLOOKUP(P28,[1]Disposition!$AB$9:$AC$495,2,0),"NO RECORD YET") -> 16 Maligaya St., Rosario 6 Subd, Sta Lucia, Pasig City 1608
A29: 21 | B29: PIO | C29: Male | D29: Pat | E29: PEÑON | F29: JAYSON | G29: CABRAL | J29: 1901 Interior, Zamora Street, Manila, NCR | K29: 09608411365 | P29: =CONCATENATE(E29," ",F29," ",G29) -> PEÑON JAYSON CABRAL | Q29: =IFERROR(VLOOKUP(P29,[1]Disposition!$AB$9:$AC$495,2,0),"NO RECORD YET") -> NO RECORD YET
A30: 22 | B30: PIO | C30: Female | D30: NUP | E30: ALVAREZ | F30: PAMELA | G30: CEREZO | J30: Pao, Manaoag, Pangasinan | K30: 09615765167 | P30: =CONCATENATE(E30," ",F30," ",G30) -> ALVAREZ PAMELA CEREZO | Q30: =IFERROR(VLOOKUP(P30,[1]Disposition!$AB$9:$AC$495,2,0),"NO RECORD YET") -> Pao, Manaoag, Pangasinan
A31: 23 | B31: PIO | C31: Male | D31: NUP | E31: RUIVIVAR | F31: JOSE SALVADOR | G31: DEL ROSARIO | J31: 13 St. Joseph St., Milton Hills Subd, Diliman, Quezon City | K31: 09770330570 | P31: =CONCATENATE(E31," ",F31," ",G31) -> RUIVIVAR JOSE SALVADOR DEL ROSARIO | Q31: =IFERROR(VLOOKUP(P31,[1]Disposition!$AB$9:$AC$495,2,0),"NO RECORD YET") -> 13 St. Joseph St., Milton Hills Subd, Diliman, Quezon City
A32: 25 | B32: SLO/OCI | C32: Female | D32: PCpl | E32: CUASAY | F32: ZAYRA JANE | G32: CEDENO | J32: 29 P Dizon Circle, Hen. T. De Leon, Valenzuela City | K32: 09953744137 | P32: =CONCATENATE(E32," ",F32," ",G32) -> CUASAY ZAYRA JANE CEDENO | Q32: =IFERROR(VLOOKUP(P32,[1]Disposition!$AB$9:$AC$495,2,0),"NO RECORD YET") -> NO RECORD YET
A33: 26 | B33: SLO/OCI | C33: Female | D33: NUP | E33: COSTALES | F33: MARY GRACE | G33: RODRIGUEZ | J33: 7C 2Nd Ave., Bagong Lipunan Ng Crame, Quezon City | K33: 09275492985 | P33: =CONCATENATE(E33," ",F33," ",G33) -> COSTALES MARY GRACE RODRIGUEZ | Q33: =IFERROR(VLOOKUP(P33,[1]Disposition!$AB$9:$AC$495,2,0),"NO RECORD YET") -> NO RECORD YET
A34: 27 | B34: SLO/OCI | C34: Female | D34: NUP | E34: VER | F34: MARIE LOUISE ROVIAN | G34: RAMOS | J34: Blk 43 Lot 16, Phase 7, Eastwood Residences, Brgy San Isidro, Montalban, Rizal | K34: 09158167417 | M34: =177-226 -> -49 | P34: =CONCATENATE(E34," ",F34," ",G34) -> VER MARIE LOUISE ROVIAN RAMOS | Q34: =IFERROR(VLOOKUP(P34,[1]Disposition!$AB$9:$AC$495,2,0),"NO RECORD YET") -> Blk 43 Lot 16, Phase 7, Eastwood Residences, Brgy San Isidro, Montalban, Rizal
A35: 28 | B35: ITPMD | C35: Male | D35: PCOL | E35: BORRES | F35: RUBEN | G35: BROSAS | J35: 163-W 20Th Avenue, Rembo, Makati City | K35: 09367450777 | P35: =CONCATENATE(E35," ",F35," ",G35) -> BORRES RUBEN BROSAS | Q35: =IFERROR(VLOOKUP(P35,[1]Disposition!$AB$9:$AC$495,2,0),"NO RECORD YET") -> NO RECORD YET
A36: 29 | B36: ITPMD | C36: Female | D36: PLTCOL | E36: FABRO | F36: JHOANA GRACIA | G36: MANLAPAZ
A37: 30 | B37: ITPMD | C37: Female | D37: NUP | E37: GONZALES | F37: NECILDA | G37: JAVINIAR | J37: 641 Blk 22 Kabisig Floodway, San Andres, Cainta, Rizal | K37: 09187708759 | P37: =CONCATENATE(E354," ",F354," ",G354) -> BATICADOS IVY ELEGARLE | Q37: =IFERROR(VLOOKUP(P37,[1]Disposition!$AB$9:$AC$495,2,0),"NO RECORD YET") -> EL Dorado Dulo, Brgy. Don Bosco, Better Living Subd., Parañaque City
A38: 31 | B38: ITPMIS, ITPMD | C38: Female | D38: PCPT | E38: QUINTOS | F38: ANGELICA | G38: AGOR | J38: B1 L128 Phase 1F, Sub Urban Village, San Jose, Montalban, Rizal | K38: 09458154169 | P38: =CONCATENATE(E38," ",F38," ",G38) -> QUINTOS ANGELICA AGOR | Q38: =IFERROR(VLOOKUP(P38,[1]Disposition!$AB$9:$AC$495,2,0),"NO RECORD YET") -> B1 L128 Phase 1F, Sub Urban Village, San Jose, Montalban, Rizal
A39: 32 | B39: ITPMIS, ITPMD | C39: Female | D39: Pat | E39: CELARIO | F39: RUBY ROSE | G39: BUEZA | J39: 37 Tagumpay St. Marawi, Camiling, Tarlac | K39: 09514992446 | N39: =566-554 -> 12 | P39: =CONCATENATE(E39," ",F39," ",G39) -> CELARIO RUBY ROSE BUEZA | Q39: =IFERROR(VLOOKUP(P39,[1]Disposition!$AB$9:$AC$495,2,0),"NO RECORD YET") -> NO RECORD YET
A40: 33 | B40: ITPMIS, ITPMD | C40: Male | D40: Pat | E40: MANAOG | F40: RODNIE | G40: CASTILLO | J40: Sitio Pongol., Brgy. Burabod, San Antonio, Northern Samar | K40: 09452066435 | N40: 3 | P40: =CONCATENATE(E40," ",F40," ",G40) -> MANAOG RODNIE CASTILLO | Q40: =IFERROR(VLOOKUP(P40,[1]Disposition!$AB$9:$AC$495,2,0),"NO RECORD YET") -> NO RECORD YET
A41: 34 | B41: ITPMIS, ITPMD | C41: Male | D41: NUP | E41: DAGTA | F41: MARY ANN | G41: YAP | J41: Blk 3, Lot 20, Amber St., Summit Viwe Subd., Brgy. San Rafael, Rodriguez, Rizal | K41: 09568629227 | P41: =CONCATENATE(E41," ",F41," ",G41) -> DAGTA MARY ANN YAP | Q41: =IFERROR(VLOOKUP(P41,[1]Disposition!$AB$9:$AC$495,2,0),"NO RECORD YET") -> Blk 3, Lot 20, Amber St., Summit Viwe Subd., Brgy. San Rafael, Rodriguez, Rizal
A42: 35 | B42: EMS, ITPMD | C42: Male | D42: PMSg | E42: PEÑAVERDE | F42: PHILIP JAMES | G42: RODRIGUEZ | J42: Blk 1 Lot 128 P1-F Sub-Urban Village, Saan Jose, Rodriguez, Rizal | K42: 09266167584 | P42: =CONCATENATE(E42," ",F42," ",G42) -> PEÑAVERDE PHILIP JAMES RODRIGUEZ | Q42: =IFERROR(VLOOKUP(P42,[1]Disposition!$AB$9:$AC$495,2,0),"NO RECORD YET") -> Blk 1 Lot 128 P1-F Sub-Urban Village, Saan Jose, Rodriguez, Rizal
...

Sheet detail Crame based
A1: Republic of the Philippines
A2: PHILIPPINE NATIONAL POLICE | J2: =259-240 -> 19
A3: INFORMATION TECHNOLOGY MANAGEMENT SERVICE | J3: =134-63 -> 71
A4: Camp Bgen Rafael T Crame, Quezon City
A6: Roster of Personnel (Detailed Crame Based)
A7: (As of January 22, 2026)
A9: NO. | B9: OFFICE/DIVISION | C9: GENDER | D9: RANK | E9: LASTNAME | F9: FIRSTNAME | G9: MIDDLE NAME | H9: QUAL | I9: SIGNATURE | J9: ADDRESS | K9: CONTACT # | P9: NAME | Q9: ADDRESS
A10: POLICE COMMISSIONED OFFICERS
A11: 1 | B11: PHAS(DICTM) | C11: Female | D11: PCOL | E11: DAMASO | F11: MARIBEL | G11: MONES | J11: 58 B, 8Th Ave., Brgy.Socorro, Cubao, Quezon City | K11: 09178740745 | P11: =CONCATENATE(E11," ",F11," ",G11) -> DAMASO MARIBEL MONES | Q11: =IFERROR(VLOOKUP(P11,[1]Disposition!$AB$9:$AC$495,2,0),"NO RECORD YET") -> 58 B, 8TH Ave., Brgy.SOcorro, Cubao, Quezon City
A12: 2 | B12: PHAS(DICTM) | C12: Male | D12: PCOL | E12: ESCOBAL | F12: CARLO JOSEPH | G12: TORRES | P12: =CONCATENATE(E12," ",F12," ",G12) -> ESCOBAL CARLO JOSEPH TORRES | Q12: =IFERROR(VLOOKUP(P12,[1]Disposition!$AB$9:$AC$495,2,0),"NO RECORD YET") -> NO RECORD YET
A13: 3 | B13: PHAS(DICTM) | C13: Male | D13: PCOL | E13: GACES | F13: JUANITO | G13: BALLUG | H13: JR | P13: =CONCATENATE(E13," ",F13," ",G13) -> GACES JUANITO BALLUG
A14: 4 | B14: PHAS(DICTM) | C14: Male | D14: PLTCOL | E14: BORJA | F14: BRIAN THEO | G14: PANGANIBAN | J14: 6 Ignacio Diaz St., Brgy. Kaunlaran, Cubao, Quezon City | K14: 09190794772 | P14: =CONCATENATE(E14," ",F14," ",G14) -> BORJA BRIAN THEO PANGANIBAN | Q14: =IFERROR(VLOOKUP(P14,[1]Disposition!$AB$9:$AC$495,2,0),"NO RECORD YET") -> 6 Ignacio Diaz St., Brgy. Kaunlaran, Cubao, Quezon City
A15: 5 | B15: ITPMD (ACG/PRO BAR) | C15: Male | D15: PLTCOL | E15: FERRANCULLO | F15: JOHN PAUL | G15: PAZ | J15: 103 Hernandez St., Old Zaniga, Mandaluyong Cityn | K15: 09987914105 | P15: =CONCATENATE(E15," ",F15," ",G15) -> FERRANCULLO JOHN PAUL PAZ | Q15: =IFERROR(VLOOKUP(P15,[1]Disposition!$AB$9:$AC$495,2,0),"NO RECORD YET") -> 103 Hernandez St., Old Zaniga, Mandaluyong CityN
A16: 6 | B16: PHAS(PRO CAR/DICTM) | C16: Male | D16: PLTCOL | E16: FONCARDAS | F16: MARK | G16: REYES | P16: =CONCATENATE(G31," ",F31," ",#REF!) -> #REF! | Q16: =IFERROR(VLOOKUP(P16,[1]Disposition!$AB$9:$AC$495,2,0),"NO RECORD YET") -> NO RECORD YET
A17: 7 | B17: ITPMD (MG/DO/RICTMD PRO12) | C17: Male | D17: PLTCOL | E17: IGNACIO | F17: MICHAEL | G17: TINTE | J17: 38 Aganan St., Zone 6, Nia Village, Quezon City | K17: 09998842166 | P17: =CONCATENATE(E17," ",F17," ",G17) -> IGNACIO MICHAEL TINTE | Q17: =IFERROR(VLOOKUP(P17,[1]Disposition!$AB$9:$AC$495,2,0),"NO RECORD YET") -> 38 Aganan St., Zone 6, NIA Village, Quezon City
A18: 8 | B18: PHAS(DICTM) | C18: Female | D18: PLTCOL | E18: MARAMAG | F18: MARCIANA | G18: DELA CRUZ | P18: =CONCATENATE(E18," ",F18," ",G18) -> MARAMAG MARCIANA DELA CRUZ | Q18: =IFERROR(VLOOKUP(P18,[1]Disposition!$AB$9:$AC$495,2,0),"NO RECORD YET") -> NO RECORD YET
A19: 9 | B19: PHAS(DICTM) | C19: Male | D19: PLTCOL | E19: REYES | F19: ROBERT | G19: ANDAL | J19: 7 Antipoli Ext., Krus Na Ligas, Quezon City | K19: 09055320909 | P19: =CONCATENATE(E19," ",F19," ",G19) -> REYES ROBERT ANDAL | Q19: =IFERROR(VLOOKUP(P19,[1]Disposition!$AB$9:$AC$495,2,0),"NO RECORD YET") -> 7 Antipoli Ext., Krus na Ligas, Quezon City
A20: 10 | B20: PHAS (RICTMD PRO4B/FS) | C20: Male | D20: PLTCOL | E20: SANTOS | F20: JAY WALTER | G20: SANTIAGO | J20: #109-B Herbosa St., Tondo, Manila | K20: 09166183905 | P20: =CONCATENATE(E20," ",F20," ",G20) -> SANTOS JAY WALTER SANTIAGO | Q20: =IFERROR(VLOOKUP(P20,[1]Disposition!$AB$9:$AC$495,2,0),"NO RECORD YET") -> #109-B Herbosa St., Tondo, Manila
A21: 11 | B21: ITPMD (DHRDD/PRO1) | C21: Male | D21: PLTCOL | E21: SEVILLA | F21: JERALD | G21: MANUZON | J21: B-38 L-20 Violeta St., Pembo, Makati City | K21: 09176055075 | P21: =CONCATENATE(E21," ",F21," ",G21) -> SEVILLA JERALD MANUZON | Q21: =IFERROR(VLOOKUP(P21,[1]Disposition!$AB$9:$AC$495,2,0),"NO RECORD YET") -> B-38 L-20 Violeta St., Pembo, Makati City
A22: 12 | B22: ITPMD (OTCDS) | C22: Male | D22: PMAJ | E22: AMIT | F22: ARIEL | G22: DE GUZMAN | J22: Manila, Metro Manila | K22: 09205682939 | P22: =CONCATENATE(#REF!," ",#REF!," ",#REF!) -> #REF! | Q22: =IFERROR(VLOOKUP(P22,[1]Disposition!$AB$9:$AC$495,2,0),"NO RECORD YET") -> NO RECORD YET
A23: 13 | B23: ITPMD (HS)/SMD | C23: Male | D23: PMAJ | E23: ANDANAR | F23: JON JASON | G23: GORGOLON | J23: B6, L2, Kingstown Subd., Brgy. 171, Caloocan City | K23: 09173197823 | P23: =CONCATENATE(E23," ",F23," ",G23) -> ANDANAR JON JASON GORGOLON | Q23: =IFERROR(VLOOKUP(P23,[1]Disposition!$AB$9:$AC$495,2,0),"NO RECORD YET") -> B6, L2, Kingstown Subd., Brgy. 171, Caloocan City
A24: 14 | B24: PHAS(DICTM) | C24: Female | D24: PMAJ | E24: BELLY | F24: JOCELYN | G24: DEL BARRIO | J24: B6 L2, Hilltop, Abatex, San Jose, Rodriguez, Rizal | K24: 09338637458 | P24: =CONCATENATE(E24," ",F24," ",G24) -> BELLY JOCELYN DEL BARRIO | Q24: =IFERROR(VLOOKUP(P24,[1]Disposition!$AB$9:$AC$495,2,0),"NO RECORD YET") -> B6 L2, Hilltop, Abatex, San Jose, Rodriguez, Rizal
A25: 15 | B25: PHAS(DICTM) | C25: Female | D25: PMAJ | E25: CRUZ | F25: MARICON | G25: TAYAMEN | J25: B6 L2 11Th Ave., Hhsg Extebsion, North Signal Village, Taguig City | K25: 09272162479 | P25: =CONCATENATE(E25," ",F25," ",G25) -> CRUZ MARICON TAYAMEN
A26: 16 | B26: ITPMD (DPRM) | C26: Male | D26: PMAJ | E26: DELA CRUZ | F26: ALVIN | G26: ORUA | J26: #6087 Sto. Rosario St., Mapulang Lupa, Valenzuela City | K26: 09178710735 | P26: =CONCATENATE(E26," ",F26," ",G26) -> DELA CRUZ ALVIN ORUA | Q26: =IFERROR(VLOOKUP(P26,[1]Disposition!$AB$9:$AC$495,2,0),"NO RECORD YET") -> #6087 Sto. Rosario St., Mapulang Lupa, Valenzuela City
A27: 17 | B27: ITPMD (DPRM) | C27: Male | D27: PMAJ | E27: DESEO | F27: REYNANTE | G27: NUYDA | J27: Blk 4 L17 Arty In Subdivision, Karuhatan, Valenzueal City | K27: 09974766710 | P27: =CONCATENATE(E27," ",F27," ",G27) -> DESEO REYNANTE NUYDA | Q27: =IFERROR(VLOOKUP(P27,[1]Disposition!$AB$9:$AC$495,2,0),"NO RECORD YET") -> Blk 4 L17 Arty in Subdivision, Karuhatan, Valenzueal City
A28: 18 | B28: ITPMD (DL) | C28: Male | D28: PMAJ | E28: DULA | F28: JOEL | G28: MANALANSAN | J28: 407 Purok 7, New San Juan, Dinalupihan, Bataan | K28: 09667058328 | P28: =CONCATENATE(E28," ",F28," ",G28) -> DULA JOEL MANALANSAN
A29: 19 | B29: ITPMD (PNP RSS) | C29: Male | D29: PMAJ | E29: ESCABOSA | F29: GEROGIL | G29: SALAZAR | J29: Blk 110 Lot 17 K-57 Kalinisan St., Karangalan V Illage, San Isidro Village, Cainta, Rizal | K29: 09171046735 | P29: =CONCATENATE(E29," ",F29," ",G29) -> ESCABOSA GEROGIL SALAZAR
A30: 20 | B30: ITPMD (EOD/K9) | C30: Male | D30: PMAJ | E30: LAXAMANA | F30: JOSE | G30: DELA CRUZ | H30: II | J30: 191 Gen. Mascardo St., Bagong Barrio, Caloocan City | K30: 09983998333 | P30: =CONCATENATE(E30," ",F30," ",G30) -> LAXAMANA JOSE DELA CRUZ
A31: 21 | B31: ITPMD (DIDM-WCPC) | C31: Male | D31: PMAJ | E31: NICOLAS | F31: JAY-R | G31: TADEO | J31: #143 Asin West., Malasigue, Pangasinan | K31: 09770935729 | P31: =CONCATENATE(#REF!," ",#REF!," ",#REF!) -> #REF!
A32: 22 | B32: ITPMD (DIDM) | C32: Male | D32: PMAJ | E32: NOBRES | F32: ROY | G32: DANGSI | J32: Lot 4-Lot 5 Metro Royale Homes Burgos, Montalban, Rizal | K32: 09178665305
A33: 23 | B33: ITPMD (CSG-SOSIA) | C33: Male | D33: PMAJ | E33: OCAMPO | F33: AMADO | G33: BISCAYDA | H33: JR | J33: 39 Constabulary St., Vet Village, Quezon City | K33: 09154810533 | P33: =CONCATENATE(#REF!," ",#REF!," ",#REF!) -> #REF! | Q33: =IFERROR(VLOOKUP(P33,[1]Disposition!$AB$9:$AC$495,2,0),"NO RECORD YET") -> NO RECORD YET
A34: 24 | B34: ITPMD (DPL) | C34: Male | D34: PMAJ | E34: SY | F34: CHRISTIAN | G34: ONG | J34: 4 | K34: 09176548452 | P34: =CONCATENATE('detail Crame based'!#REF!," ",'detail Crame based'!#REF!," ",'detail Crame based'!#REF!) -> #REF! | Q34: =IFERROR(VLOOKUP(P34,[1]Disposition!$AB$9:$AC$495,2,0),"NO RECORD YET") -> NO RECORD YET
A35: 25 | B35: PHAS(DICTM) | C35: Male | D35: PMAJ | E35: TAN | F35: ROBERT | G35: BACALTOS | J35: 847 Tahimik St., Delpan, Tondo, Manila | K35: 09176860807 | P35: =CONCATENATE(E35," ",F35," ",G35) -> TAN ROBERT BACALTOS | Q35: =IFERROR(VLOOKUP(P35,[1]Disposition!$AB$9:$AC$495,2,0),"NO RECORD YET") -> 847 Tahimik St., Delpan, Tondo, Manila
A36: 26 | B36: ITPMD (PSPG) | C36: Male | D36: PCPT | E36: ABUAN | F36: DICKSON | G36: CLEMENTE | J36: 735 Purok 4B, Lucnab Baguio City | K36: 09481748796 | P36: =CONCATENATE(E36," ",F36," ",G36) -> ABUAN DICKSON CLEMENTE
A37: 27 | B37: ITPMD (PIO) | C37: Male | D37: PCPT | E37: ALIMAMBO | F37: JICK | G37: BONUAN | J37: 72 Pucay Village, Purok I, Bakakeng Norte, Baguio City | K37: 09774274007 | P37: =CONCATENATE(E37," ",F37," ",G37) -> ALIMAMBO JICK BONUAN | Q37: =IFERROR(VLOOKUP(P37,[1]Disposition!$AB$9:$AC$495,2,0),"NO RECORD YET") -> 72 Pucay Village, Purok I, Bakakeng Norte, Baguio City
A38: 28 | B38: PHAS (CICC) | C38: Male | D38: PCPT | E38: ANURAN | F38: ADRIAN | G38: MIRASOL | J38: 57 A Delas Alas St., Zone 13, Taal, Batangas | K38: 09065467212 | P38: =CONCATENATE(E38," ",F38," ",G38) -> ANURAN ADRIAN MIRASOL | Q38: =IFERROR(VLOOKUP(P38,[1]Disposition!$AB$9:$AC$495,2,0),"NO RECORD YET") -> 57 A Delas Alas St., Zone 13, Taal, Batangas
A39: 29 | B39: ITPMD (CSG-FEO) | C39: Male | D39: PCPT | E39: BALICAG | F39: JOSE | G39: DAKETAN | H39: JR | J39: Block 3, D Molintas, Bulanao, Tabuk City Kalinga | K39: 09303641739 | P39: =CONCATENATE(E39," ",F39," ",G39) -> BALICAG JOSE DAKETAN
A40: 30 | B40: ITPMD (DC) | C40: Male | D40: PCPT | E40: BALLENAS | F40: ROBERTO | G40: ALPAS | H40: JR | J40: Purok Masipag, Buayan, M'Lang, Cotabato, North Cotabato | K40: 09664625855 | P40: =CONCATENATE(E40," ",F40," ",G40) -> BALLENAS ROBERTO ALPAS | Q40: =IFERROR(VLOOKUP(P40,[1]Disposition!$AB$9:$AC$495,2,0),"NO RECORD YET") -> Purok Masipag, Buayan, M'lang, Cotabato, North Cotabato
A41: 31 | B41: PHAS(DICTM) | C41: Male | D41: PCPT | E41: BATALLER | F41: SHERWIN SOLOMON | G41: BELLEN | H41: III | J41: J Rizal St., Paciano Rizal, Calamba City, Laguna | K41: 09175121981 | P41: =CONCATENATE(#REF!," ",#REF!," ",#REF!) -> #REF! | Q41: =IFERROR(VLOOKUP(P41,[1]Disposition!$AB$9:$AC$495,2,0),"NO RECORD YET") -> NO RECORD YET
A42: 32 | B42: ITPMD (PNPTS) | C42: Male | D42: PCPT | E42: BAYAUA | F42: ANGELO | G42: ZALUN | J42: B10 L23 P-H Guijo, Francisco Homes , Sjdm, Bulacan | K42: 09171108106 | P42: =CONCATENATE(E42," ",F42," ",G42) -> BAYAUA ANGELO ZALUN | Q42: =IFERROR(VLOOKUP(P42,[1]Disposition!$AB$9:$AC$495,2,0),"NO RECORD YET") -> B10 L23 P-H Guijo, Francisco Homes , SJDM, Bulacan
...

Sheet itmsHQ
A1: Republic of the Philippines
A2: PHILIPPINE NATIONAL POLICE
A3: INFORMATION TECHNOLOGY MANAGEMENT SERVICE
A4: Camp Bgen Rafael T Crame, Quezon City
A6: Roster of Personnel (ITMSHQ Only)
A7: (As of January 22, 2026)
A9: NO. | B9: OFFICE/DIVISION | C9: GENDER | D9: RANK | E9: LASTNAME | F9: FIRSTNAME | G9: MIDDLE NAME | H9: QUAL | I9: SIGNATURE
A10: POLICE COMMISSIONED OFFICERS
A11: 1 | B11: PTD | C11: Female | D11: PCOL | E11: ALI | F11: SHIRLEY MAE | G11: SALVADOR
A12: 2 | B12: ITPMD | C12: Male | D12: PCOL | E12: BORRES | F12: RUBEN | G12: BROSAS
A13: 3 | B13: ARMD | C13: Male | D13: PCOL | E13: DELA PEÑA | F13: VICTORIO | G13: MENDIOLA | H13: JR
A14: 4 | B14: DMD | C14: Male | D14: PCOL | E14: JOAQUIN | F14: ROMEO | G14: LISING
A15: 5 | B15: OD | C15: Male | D15: PCOL | E15: PALGUE | F15: ROMY | G15: INWAY
A16: 6 | B16: OCS | C16: Male | D16: PCOL | E16: PATIÑO | F16: RANDI | G16: MANZANO
A17: 7 | B17: ODDA/DI | C17: Male | D17: PCOL | E17: TANGO | F17: FROILAN GENN | G17: GELACIO | H17: II
A18: 8 | B18: BFS/LS/IHSS/PRO12 | C18: Male | D18: PLTCOL | E18: AQUINO | F18: JOHANNES GOLD | G18: LUCERO
A19: 9 | B19: BFS, ARMD | C19: Male | D19: PLTCOL | E19: BALMACEDA | F19: ROMMEL | G19: BANGUILAN
A20: 10 | B20: ITPMD | C20: Female | D20: PLTCOL | E20: FABRO | F20: JHOANA GRACIA | G20: MANLAPAZ
A21: 11 | B21: SMD/RICTMD PRO 9 | C21: Male | D21: PLTCOL | E21: RIMANDO | F21: JUVENAL | G21: AFOS
A22: 12 | B22: ISSD | C22: Male | D22: PLTCOL | E22: SANTOS | F22: NHARCISO JHOEL | G22: SULIT
A23: 13 | B23: ARMD | C23: Female | D23: PLTCOL | E23: SUCGANG | F23: ROSE ANNE | G23: ROXAS
A24: 14 | B24: DMD/PRO13 | C24: Male | D24: PLTCOL | E24: TARUN | F24: CHRISTIAN | G24: BELTRAN
A25: 15 | B25: PHAS (RICTMD PRO13) | C25: Male | D25: PLTCOL | E25: VIRTUDAZO | F25: MICHAEL | G25: TAREPE
A26: 16 | B26: TSS, PTD | C26: Female | D26: PCPT | E26: AGUSTIN | F26: RIZELLE | G26: INALDO
A27: 17 | B27: ITPMD (PIO) | C27: Male | D27: PCPT | E27: ALIMAMBO | F27: JICK | G27: BONUAN
A28: 18 | B28: SMD | C28: Male | D28: PCPT | E28: ANISCO | F28: ARCHIE | G28: STO.DOMINGO
A29: 19 | B29: IT Help Desk SAS, ITSD | C29: Male | D29: PCPT | E29: CABILES | F29: FIDEL | G29: VALEROS
... A31: 21 | B31: OCS | C31: Male | D31: PCPT | E31: KARIM | F31: BENSAR ALI | G31: ABDULGANI
A32: 22 | B32: PHAS, ARMD | C32: Male | D32: PCPT | E32: LOPEZ | F32: JOEL | G32: MORATALLA | H32: JR
A33: 23 | B33: ISSD | C33: Male | D33: PCPT | E33: ONIL | F33: RELLON | G33: SUAYAN
A34: 24 | B34: SMD | C34: Male | D34: PCPT | E34: PAPIÑA | F34: PATRICK LYNDON | G34: PARCAREY
A35: 25 | B35: PS, ARMD | C35: Male | D35: PCPT | E35: SYTICO | F35: JAMES | G35: ALCERA
A36: 26 | B36: SMD | C36: Male | D36: PCPT | E36: ULPINDO | F36: KRISANTO | G36: TAPIA
A37: 27 | B37: TS, PTD | C37: Male | D37: PLT | E37: ARIAS | F37: AUDEN | G37: GOZUM
A38: 28 | B38: ITSD | C38: Male | D38: PLT | E38: BANTIYAN | F38: JEFTER | G38: PAKID
A39: 29 | B39: ISSD | C39: Male | D39: PLT | E39: CORPUZ | F39: ALEX ACE | G39: CABAUATAN
A40: 30 | B40: DWBIS, DMD | C40: Male | D40: PLT | E40: DAVID | F40: EDUARDO | G40: BALATIAN | H40: JR
A41: 31 | B41: ITSD | C41: Male | D41: PLT | E41: GUIFAYA | F41: GILBERT | G41: ULIDAN | H41: JR
A42: 32 | B42: ICRMS, ARMD | C42: Female | D42: PLT | E42: PAMITTAN | F42: JOCELYN | G42: LATTAO
A43: 33 | B43: SMD | C43: Male | D43: PLT | E43: PARRE | F43: WINSTON | G43: SAFLOR
...

Sheet Disposition
A1: NATIONAL POLICE COMMISSION
A2: PHILIPPINE NATIONAL POLICE
A3: INFORMATION TECHNOLOGY MANAGEMENT SERVICE
A4: Camp Bgen Rafael T Crame, Quezon City
A6: Disposition of Personnel
A7: (As of September 7, 2026) | J7: =SUM(9+0+1) -> 10
A9: NO. | B9: OFFICE/DIVISION | C9: GENDER | D9: RANK | E9: LASTNAME | F9: FIRSTNAME | G9: MIDDLE NAME | H9: QUAL | I9: DESIGNATION | J9: ADDRESS | K9: CONTACT # | P9: NAME | Q9: ADDRESS
A10: 1 | B10: OD | C10: Male | D10: PBGEN | E10: PALGUE | F10: ROMY | G10: INWAY | I10: Director | J10: Imugan, Sta. Fe, Nueva Vizcaya | K10: 09175304121
A11: 2 | B11: OD | C11: Male | D11: PCpl | E11: CERIL | F11: PAUL KELVIN | G11: LAROZA | I11: Duty PNCO | J11: Purok Saranay, Palabotan, Dupax Del Sur, Nueva Vizcaya | K11: 09165565299
A12: 3 | B12: OD | C12: Male | D12: Pat | E12: BEJARIN | F12: GERALD | G12: DADIRO | I12: Duty PNCO | J12: Riang, Peñarrubia, Abra | K12: 09368167960 | P12: =CONCATENATE(E12," ",F12," ",G12) -> BEJARIN GERALD DADIRO | Q12: =IFERROR(VLOOKUP(P12,[1]Disposition!$AB$9:$AC$495,2,0),"NO RECORD YET") -> NO RECORD YET
A13: 4 | B13: OD | C13: Male | D13: Pat | E13: MORI | F13: LYNDON | G13: ACOSTA | I13: Duty PNCO | J13: Caimito, Brgy. Buencag, Gerona, Tarlac | K13: 09091819560 | P13: =CONCATENATE(E13," ",F13," ",G13) -> MORI LYNDON ACOSTA | Q13: =IFERROR(VLOOKUP(P13,[1]Disposition!$AB$9:$AC$495,2,0),"NO RECORD YET") -> NO RECORD YET
A14: 5 | B14: OD | C14: Female | D14: NUP | E14: AVENDAÑO | F14: MA. FRELIE JOY | G14: (no middle name) | I14: ISR II (SG14) | J14: #92 F Estrella St., San Juan, Malolos City, Bulacan | K14: 09554289264 | P14: =CONCATENATE(E14," ",F14," ",G14) -> AVENDAÑO MA. FRELIE JOY (no middle name) | Q14: =IFERROR(VLOOKUP(P14,[1]Disposition!$AB$9:$AC$495,2,0),"NO RECORD YET") -> #92 F Estrella St., San Juan, Malolos City, Bulacan
A15: 6 | B15: OD | C15: Female | D15: NUP | E15: DALLEGO | F15: RHIZA | G15: ARROYO | I15: Supply Accountable Officer | J15: Mb26 U109 Pamayanang Diego Silang, Brgy. Ususan, Taguig City | K15: 09950858301 | P15: =CONCATENATE(E15," ",F15," ",G15) -> DALLEGO RHIZA ARROYO | Q15: =IFERROR(VLOOKUP(P15,[1]Disposition!$AB$9:$AC$495,2,0),"NO RECORD YET") -> MB26 U109 Pamayanang Diego Silang, Brgy. Ususan, Taguig City
A16: 7 | B16: OD | C16: Female | D16: NUP | E16: LUZARA | F16: JEAN | G16: GRATUITO | I16: Training Specialist I (SG11) | J16: Blk 5 Lot 1 Orchid Extension, Capitol Park Homes Ii, Brgy 179 Zone 16, Caloocan City. | K16: 09177037934 | P16: =CONCATENATE(E16," ",F16," ",G16) -> LUZARA JEAN GRATUITO | Q16: =IFERROR(VLOOKUP(P16,[1]Disposition!$AB$9:$AC$495,2,0),"NO RECORD YET") -> Blk 5 Lot 1 Orchid Extension, Capitol Park Homes II, Brgy 179 Zone 16, Caloocan City.
A17: 8 | B17: ODDA | C17: Male | D17: PCOL | E17: TAGAO | F17: RONALD | G17: MIGUEL | I17: Deputy Director for Admin.
A18: 9 | B18: ODDA/ PRO13 | C18: Male | D18: PLTCOL | E18: TARUN | F18: CHRISTIAN | G18: BELTRAN | I18: BACSEC/ IT Project Officer | J18: 110B. Harrison Street, Vermont Park, Mayamot, Antipolo City, Rizal | K18: 09178359985 | P18: =CONCATENATE(E18," ",F18," ",G18) -> TARUN CHRISTIAN BELTRAN | Q18: =IFERROR(VLOOKUP(P18,[1]Disposition!$AB$9:$AC$495,2,0),"NO RECORD YET") -> 110B. Harrison Street, Vermont Park, Mayamot, Antipolo City, Rizal
A19: 10 | B19: ODDA | C19: Male | D19: PSSg | E19: CHAN | F19: HAROLD JAY | G19: AMAZONA | I19: Duty PNCO | P19: =CONCATENATE(E19," ",F19," ",G19) -> CHAN HAROLD JAY AMAZONA
A20: 11 | B20: ODDA | C20: Female | D20: NUP | E20: ERIBAL | F20: JOZEL JOY | G20: FALAGNE | I20: Administrative Assistant III (SG9) (DMD) | J20: 5A Diamond St., Jra Subd., Rosario, Pasug City | K20: 09617215961 | P20: =CONCATENATE(E20," ",F20," ",G20) -> ERIBAL JOZEL JOY FALAGNE | Q20: =IFERROR(VLOOKUP(P20,[1]Disposition!$AB$9:$AC$495,2,0),"NO RECORD YET") -> 5A Diamond St., JRA Subd., Rosario, Pasug City
A21: 12 | B21: ODDA | C21: Female | D21: NUP | E21: SEMILLA | F21: FLORITES | G21: SARIO | I21: Administrative Asst V (SG 11) | J21: 18 C Dungo St., Brgy, Isabelita, San Juan City | K21: 09274390528 | P21: =CONCATENATE(E21," ",F21," ",G21) -> SEMILLA FLORITES SARIO
A22: 13 | B22: DD for IT Matters | C22: Female | D22: NUP | E22: MATILLANO | F22: MINA HAYDEE | G22: BECERA | I22: DD IT(SG25) | J22: B2 L17 Rose St., Venice Homes Subd., Cainta, Rizal | K22: 09266411836 | P22: =CONCATENATE(E22," ",F22," ",G22) -> MATILLANO MINA HAYDEE BECERA | Q22: =IFERROR(VLOOKUP(P22,[1]Disposition!$AB$9:$AC$495,2,0),"NO RECORD YET") -> B2 L17 Rose St., Venice Homes Subd., Cainta, Rizal
A23: 14 | B23: ODDIT | C23: Female | D23: NUP | E23: BAGO | F23: REBECCA | G23: LLANEZA | I23: Administrative Assistant VI (SG12) | J23: 196 Guyam Malaki, Indang, Cavite | K23: 09278398862 | P23: =CONCATENATE(E23," ",F23," ",G23) -> BAGO REBECCA LLANEZA | Q23: =IFERROR(VLOOKUP(P23,[1]Disposition!$AB$9:$AC$495,2,0),"NO RECORD YET") -> 196 Guyam Malaki, Indang, Cavite
A24: 15 | B24: ODDIT | C24: Female | D24: NUP | E24: CAADAN | F24: JENNYFER | G24: PISCO | I24: Administrative Aide VI (SG6) | J24: 65 Lower Molave St. Payatas B, QC | K24: 9294573659
A25: 16 | B25: OCS | C25: Male | D25: PCOL | E25: PATIÑO | F25: RANDI | G25: MANZANO | I25: Chief of Staff/Chief, PSMU | J25: Mddle Nivel Hills, Brgy Apas, Cebu City | K25: 09057369133 | P25: =CONCATENATE(E25," ",F25," ",G25) -> PATIÑO RANDI MANZANO | Q25: =IFERROR(VLOOKUP(P25,[1]Disposition!$AB$9:$AC$495,2,0),"NO RECORD YET") -> Mddle Nivel Hills, Brgy Apas, Cebu City
A26: 17 | B26: OCS | C26: Male | D26: PCPT | E26: KARIM | F26: BENSAR ALI | G26: ABDULGANI | I26: Secretary of the Chief of Staff | J26: 21-B Maguindanao St, Culiat, Quezon City | K26: 09267388655 | P26: =CONCATENATE(E26," ",F26," ",G26) -> KARIM BENSAR ALI ABDULGANI | Q26: =IFERROR(VLOOKUP(P26,[1]Disposition!$AB$9:$AC$495,2,0),"NO RECORD YET") -> 21-B Maguindanao St, Culiat, Quezon City
A27: 18 | B27: OCS | C27: Male | D27: PCpl | E27: AGGARAO | F27: ALBERTO | G27: CALLANGAN | I27: Action PNCO | J27: 215 D Guiho St., Cembo, Makati City | K27: 09434383476 | P27: =CONCATENATE(E27," ",F27," ",G27) -> AGGARAO ALBERTO CALLANGAN | Q27: =IFERROR(VLOOKUP(P27,[1]Disposition!$AB$9:$AC$495,2,0),"NO RECORD YET") -> 215 D Guiho St., Cembo, Makati City
A28: 19 | B28: OCS | C28: Female | D28: PCpl | E28: SANG-AN | F28: CATHERINE | G28: VALDESTAMON | I28: Secretary | J28: Zone 1 Purok Maligaya, Tagburos, Puerto Princesa City, Palawan | K28: 09279979400 | P28: =CONCATENATE(E28," ",F28," ",G28) -> SANG-AN CATHERINE VALDESTAMON | Q28: =IFERROR(VLOOKUP(P28,[1]Disposition!$AB$9:$AC$495,2,0),"NO RECORD YET") -> NO RECORD YET
A29: 20 | B29: OCS | C29: Female | D29: NUP | E29: ESTEVES | F29: MARICEL | G29: FRESNOZA | I29: Information Systems Researcher (SG10) | J29: 3310 Bataan St., Bacood, Sta.Mesa, Manila | K29: 09293473925 | P29: =CONCATENATE(E29," ",F29," ",G29) -> ESTEVES MARICEL FRESNOZA | Q29: =IFERROR(VLOOKUP(P29,[1]Disposition!$AB$9:$AC$495,2,0),"NO RECORD YET") -> 3310 Bataan St., Bacood, Sta.Mesa, Manila
A30: 21 | B30: PIO | C30: Male | D30: Pat | E30: PEÑON | F30: JAYSON | G30: CABRAL | I30: Duty PNCO/CSG (creation of AVP) | J30: 1901 Interior, Zamora Street, Manila, NCR | K30: 09608411365 | P30: =CONCATENATE(E30," ",F30," ",G30) -> PEÑON JAYSON CABRAL | Q30: =IFERROR(VLOOKUP(P30,[1]Disposition!$AB$9:$AC$495,2,0),"NO RECORD YET") -> NO RECORD YET
A31: 22 | B31: PIO | C31: Female | D31: NUP | E31: ALVAREZ | F31: PAMELA | G31: CEREZO | I31: PIO/PCR Staff (SG7) | J31: Pao, Manaoag, Pangasinan | K31: 09615765167 | P31: =CONCATENATE(E31," ",F31," ",G31) -> ALVAREZ PAMELA CEREZO | Q31: =IFERROR(VLOOKUP(P31,[1]Disposition!$AB$9:$AC$495,2,0),"NO RECORD YET") -> Pao, Manaoag, Pangasinan
A32: 23 | B32: PIO | C32: Male | D32: NUP | E32: RUIVIVAR | F32: JOSE SALVADOR | G32: DEL ROSARIO | I32: OIC, PIO/PCR Staff (SG14) | J32: 13 St. Joseph St., Milton Hills Subd, Diliman, Quezon City | K32: 09770330570 | P32: =CONCATENATE(E32," ",F32," ",G32) -> RUIVIVAR JOSE SALVADOR DEL ROSARIO | Q32: =IFERROR(VLOOKUP(P32,[1]Disposition!$AB$9:$AC$495,2,0),"NO RECORD YET") -> 13 St. Joseph St., Milton Hills Subd, Diliman, Quezon City
A33: 24 | B33: SLO/OCI | C33: Female | D33: PMAJ | E33: UNTALAN | F33: EDUARDO | G33: SANTOS | H33: II | I33: Servicing Legal Officer | J33: Purok 5, Santa Cruz, Bagabag, Nueva Vizcaya | K33: 09178334438 | P33: =CONCATENATE(E33," ",F33," ",G33) -> UNTALAN EDUARDO SANTOS
A34: 25 | B34: SLO/OCI/ARMD | C34: Male | D34: PMSg | E34: CANJA | F34: ROBERTO | G34: GINETA | H34: JR | I34: Duty PNCO/OIC, C, Clerk, ARMD | J34: Brgy. Mambabanga, Luna, Isabela | K34: 09350231418 | P34: =CONCATENATE(E34," ",F34," ",G34) -> CANJA ROBERTO GINETA | Q34: =IFERROR(VLOOKUP(P34,[1]Disposition!$AB$9:$AC$495,2,0),"NO RECORD YET") -> Brgy. Mambabanga, Luna, Isabela
A35: 26 | B35: SLO/OCI | C35: Female | D35: PCpl | E35: CUASAY | F35: ZAYRA JANE | G35: CEDENO | I35: Duty PNCO | J35: 29 P Dizon Circle, Hen. T. De Leon, Valenzuela City | K35: 09953744137 | P35: =CONCATENATE(E35," ",F35," ",G35) -> CUASAY ZAYRA JANE CEDENO | Q35: =IFERROR(VLOOKUP(P35,[1]Disposition!$AB$9:$AC$495,2,0),"NO RECORD YET") -> NO RECORD YET
A36: 27 | B36: SLO/OCI | C36: Female | D36: NUP | E36: COSTALES | F36: MARY GRACE | G36: RODRIGUEZ | I36: Computer Programmjer (SG11) | J36: 7C 2Nd Ave., Bagong Lipunan Ng Crame, Quezon City | K36: 09275492985 | P36: =CONCATENATE(E36," ",F36," ",G36) -> COSTALES MARY GRACE RODRIGUEZ | Q36: =IFERROR(VLOOKUP(P36,[1]Disposition!$AB$9:$AC$495,2,0),"NO RECORD YET") -> NO RECORD YET
A37: 28 | B37: SLO/OCI | C37: Female | D37: NUP | E37: VER | F37: MARIE LOUISE ROVIAN | G37: RAMOS | I37: Administrative Assistant I (SG7) | J37: Blk 43 Lot 16, Phase 7, Eastwood Residences, Brgy San Isidro, Montalban, Rizal | K37: 09158167417 | P37: =CONCATENATE(E37," ",F37," ",G37) -> VER MARIE LOUISE ROVIAN RAMOS | Q37: =IFERROR(VLOOKUP(P37,[1]Disposition!$AB$9:$AC$495,2,0),"NO RECORD YET") -> Blk 43 Lot 16, Phase 7, Eastwood Residences, Brgy San Isidro, Montalban, Rizal
A38: 29 | B38: PSMU | C38: Female | D38: Pat | E38: CELARIO | F38: RUBY ROSE | G38: BUEZA | I38: Staff, SMAS, PSMU | J38: 37 Tagumpay St. Marawi, Camiling, Tarlac | K38: 09514992446 | P38: =CONCATENATE(E38," ",F38," ",G38) -> CELARIO RUBY ROSE BUEZA | Q38: =IFERROR(VLOOKUP(P38,[1]Disposition!$AB$9:$AC$495,2,0),"NO RECORD YET") -> NO RECORD YET
A39: 30 | B39: PSMU | C39: Female | D39: NUP | E39: DAGUPLO | F39: ROSETTE | G39: CASTILLO | I39: Administrative Aide VI (SG6) (DMD) | P39: =CONCATENATE(E39," ",F39," ",G39) -> DAGUPLO ROSETTE CASTILLO
A40: 31 | B40: PSMU | C40: Female | D40: NUP | E40: FRANDO | F40: DANICA | G40: DATO-ON | I40: Administrative Aide VI (SG6) (DMD) | P40: =CONCATENATE(E40," ",F40," ",G40) -> FRANDO DANICA DATO-ON
A41: 32 | B41: PSMU | C41: Female | D41: NUP | E41: NABONG | F41: WENDA GREEN LINDON | G41: TOMAS | I41: Staff, Change Mgmt and Best Practices, SRS (SG6) | P41: =CONCATENATE(E41," ",F41," ",G41) -> NABONG WENDA GREEN LINDON TOMAS
A42: 33 | B42: PSMU | C42: Female | D42: NUP | E42: QUIJANO | F42: SHEILA MARIE | G42: VELARDE | I42: Administrative Aide VI (SG6) (DMD) | P42: =CONCATENATE(E42," ",F42," ",G42) -> QUIJANO SHEILA MARIE VELARDE
...

Sheet Alpha List
A1: Republic of the Philippines
A2: NATIONAL POLICE COMMISSION
A3: PHILIPPINE NATIONAL POLICE
A4: INFORMATION TECHNOLOGY MANAGEMENT SERVICE
A6: ALPHA LIST
A7: (As of September 7, 2026)
A8: NO. | B8: RANK | C8: STATUS | D8: BADGE NO/SG | E8: LAST NAME | F8: FIRST NAME | G8: MIDDLE NAME | H8: QUAL. | I8: AGE TO DATE | J8: Birthdate | K8: AGE OF SERVICE TO DATE | L8: DES (UP) | M8: PNCO | N8: NUP | O8: OFFICE/DIVISION | P8: DESIGNATION
A9: 1 | B9: PCPT | C9: PERM | D9: O-36665 | E9: ABANILLA | F9: FREDDIE | G9: BAUTISTA | I9: =DATEDIF(J9,DATE(2026,4,30),"y")&" years, "&DATEDIF(J9,DATE(2026,4,30),"ym")&" month(s), "&DATEDIF(J9,DATE(2026,4,30),"md")&" day(s)" -> 34 years, 7 month(s), 19 day(s) | J9: 33492 | K9: =DATEDIF(L9,DATE(2026,4,30),"y")&" years, "&DATEDIF(L9,DATE(2026,4,30),"ym")&" month(s), "&DATEDIF(L9,DATE(2026,4,30),"md")&" day(s)" -> 4 years, 5 month(s), 26 day(s) | L9: 44504 | M9: 41619 | O9: ITPMD (SAF) | P9: IT Project Officer
A10: 2 | B10: PCpl | C10: PERM | D10: 311622 | E10: ABDUHARI | F10: AL-MITRA | G10: PUNGUTAN | I10: =DATEDIF(J10,DATE(2026,4,30),"y")&" years, "&DATEDIF(J10,DATE(2026,4,30),"ym")&" month(s), "&DATEDIF(J10,DATE(2026,4,30),"md")&" day(s)" -> 38 years, 6 month(s), 6 day(s) | J10: 32074 | K10: =DATEDIF(L10,DATE(2026,4,30),"y")&" years, "&DATEDIF(L10,DATE(2026,4,30),"ym")&" month(s), "&DATEDIF(L10,DATE(2026,4,30),"md")&" day(s)" -> 8 years, 7 month(s), 14 day(s) | L10: 42994 | O10: ITPMD (PRO9) | P10: IT Project PNCO
A11: 3 | B11: PCPT | C11: PERM | D11: O-37277 | E11: ABO | F11: MARK JESSIE | G11: MELITANTE | I11: =DATEDIF(J11,DATE(2026,4,30),"y")&" years, "&DATEDIF(J11,DATE(2026,4,30),"ym")&" month(s), "&DATEDIF(J11,DATE(2026,4,30),"md")&" day(s)" -> 31 years, 1 month(s), 27 day(s) | J11: 34761 | K11: =DATEDIF(L11,DATE(2026,4,30),"y")&" years, "&DATEDIF(L11,DATE(2026,4,30),"ym")&" month(s), "&DATEDIF(L11,DATE(2026,4,30),"md")&" day(s)" -> 6 years, 6 month(s), 9 day(s) | L11: 43759 | O11: ITPMD (DIDM) | P11: IT Project Officer
A12: 4 | B12: Pat | C12: PERM | D12: 376371 | E12: ABONG | F12: MARK CLENTON | G12: (NO MIDDLE NAME) | I12: =DATEDIF(J12,DATE(2026,4,30),"y")&" years, "&DATEDIF(J12,DATE(2026,4,30),"ym")&" month(s), "&DATEDIF(J12,DATE(2026,4,30),"md")&" day(s)" -> 28 years, 3 month(s), 28 day(s) | J12: 35797 | K12: =DATEDIF(L12,DATE(2026,4,30),"y")&" years, "&DATEDIF(L12,DATE(2026,4,30),"ym")&" month(s), "&DATEDIF(L12,DATE(2026,4,30),"md")&" day(s)" -> 3 years, 4 month(s), 3 day(s) | L12: 44922 | O12: ITPMD (NIR) | P12: IT Project PNCO
A13: 5 | B13: Pat | C13: PERM | D13: 375615 | E13: ABRIAM | F13: ANNETH VALERIE | G13: MALNAT | I13: =DATEDIF(J13,DATE(2026,4,30),"y")&" years, "&DATEDIF(J13,DATE(2026,4,30),"ym")&" month(s), "&DATEDIF(J13,DATE(2026,4,30),"md")&" day(s)" -> 28 years, 4 month(s), 4 day(s) | J13: 35790 | K13: =DATEDIF(L13,DATE(2026,4,30),"y")&" years, "&DATEDIF(L13,DATE(2026,4,30),"ym")&" month(s), "&DATEDIF(L13,DATE(2026,4,30),"md")&" day(s)" -> 3 years, 5 month(s), 16 day(s) | L13: 44879 | O13: ITPMD (DIDM) | P13: IT Project PNCO
A14: 6 | B14: PCPT | C14: PERM | D14: O-36426 | E14: ABUAN | F14: DICKSON | G14: CLEMENTE | I14: =DATEDIF(J14,DATE(2026,4,30),"y")&" years, "&DATEDIF(J14,DATE(2026,4,30),"ym")&" month(s), "&DATEDIF(J14,DATE(2026,4,30),"md")&" day(s)" -> 34 years, 1 month(s), 13 day(s) | J14: 33680 | K14: =DATEDIF(L14,DATE(2026,4,30),"y")&" years, "&DATEDIF(L14,DATE(2026,4,30),"ym")&" month(s), "&DATEDIF(L14,DATE(2026,4,30),"md")&" day(s)" -> 4 years, 7 month(s), 14 day(s) | L14: 44455 | M14: 42562 | O14: ITPMD (PSPG) | P14: IT Project Officer
A15: 7 | B15: NUP | C15: PERM | D15: 7 | E15: ACORDA | F15: ELPIDIO | G15: PALARCA | I15: =DATEDIF(J15,DATE(2026,4,30),"y")&" years, "&DATEDIF(J15,DATE(2026,4,30),"ym")&" month(s), "&DATEDIF(J15,DATE(2026,4,30),"md")&" day(s)" -> 63 years, 2 month(s), 12 day(s) | J15: 23060 | K15: =DATEDIF(L15,DATE(2026,4,30),"y")&" years, "&DATEDIF(L15,DATE(2026,4,30),"ym")&" month(s), "&DATEDIF(L15,DATE(2026,4,30),"md")&" day(s)" -> 43 years, 11 month(s), 29 day(s) | L15: 30072 | O15: ICRMS, ARMD | P15: Liaison Officer (SG7)
A16: 8 | B16: NUP | C16: PERM | D16: 17 | E16: ACUESTA | F16: ANA JUNE | G16: FORRO | I16: =DATEDIF(J16,DATE(2026,4,30),"y")&" years, "&DATEDIF(J16,DATE(2026,4,30),"ym")&" month(s), "&DATEDIF(J16,DATE(2026,4,30),"md")&" day(s)" -> 37 years, 10 month(s), 19 day(s) | J16: 32305 | K16: =DATEDIF(L16,DATE(2026,4,30),"y")&" years, "&DATEDIF(L16,DATE(2026,4,30),"ym")&" month(s), "&DATEDIF(L16,DATE(2026,4,30),"md")&" day(s)" -> 14 years, 6 month(s), 16 day(s) | L16: 40830 | O16: SPIS, SMD | P16: Info Systems Researcher (SG17)
A17: 9 | B17: NUP | C17: PERM | D17: 15 | E17: ADULTA | F17: ARREN LEE | G17: CHACON | I17: =DATEDIF(J17,DATE(2026,4,30),"y")&" years, "&DATEDIF(J17,DATE(2026,4,30),"ym")&" month(s), "&DATEDIF(J17,DATE(2026,4,30),"md")&" day(s)" -> 40 years, 11 month(s), 20 day(s) | J17: 31177 | K17: =DATEDIF(L17,DATE(2026,4,30),"y")&" years, "&DATEDIF(L17,DATE(2026,4,30),"ym")&" month(s), "&DATEDIF(L17,DATE(2026,4,30),"md")&" day(s)" -> 12 years, 5 month(s), 9 day(s) | L17: 41599 | O17: HMS, ITSD | P17: Comp. Maintenance Tech. II (SG15)
A18: 10 | B18: PCpl | C18: PERM | D18: 196791 | E18: AGGARAO | F18: ALBERTO | G18: CALLANGAN | I18: =DATEDIF(J18,DATE(2026,4,30),"y")&" years, "&DATEDIF(J18,DATE(2026,4,30),"ym")&" month(s), "&DATEDIF(J18,DATE(2026,4,30),"md")&" day(s)" -> 42 years, 10 month(s), 13 day(s) | J18: 30484 | K18: =DATEDIF(L18,DATE(2026,4,30),"y")&" years, "&DATEDIF(L18,DATE(2026,4,30),"ym")&" month(s), "&DATEDIF(L18,DATE(2026,4,30),"md")&" day(s)" -> 16 years, 9 month(s), 29 day(s) | L18: 39995 | O18: OCS | P18: Action PNCO
A19: 11 | B19: Pat | C19: PERM | D19: 382567 | E19: AGOS | F19: CELSO | G19: TAPONG | H19: JR | I19: =DATEDIF(J19,DATE(2026,4,30),"y")&" years, "&DATEDIF(J19,DATE(2026,4,30),"ym")&" month(s), "&DATEDIF(J19,DATE(2026,4,30),"md")&" day(s)" -> 32 years, 11 month(s), 29 day(s) | J19: 34090 | K19: =DATEDIF(L19,DATE(2026,4,30),"y")&" years, "&DATEDIF(L19,DATE(2026,4,30),"ym")&" month(s), "&DATEDIF(L19,DATE(2026,4,30),"md")&" day(s)" -> 1 years, 4 month(s), 15 day(s) | L19: 45641 | N19: 44935 | O19: DMD/DO | P19: Duty PNCO/IT PNCO
A20: 12 | B20: NUP | C20: PERM | D20: 6 | E20: AGRIPA | F20: PAUL KENNETH | G20: DE GUZMAN | I20: =DATEDIF(J20,DATE(2026,4,30),"y")&" years, "&DATEDIF(J20,DATE(2026,4,30),"ym")&" month(s), "&DATEDIF(J20,DATE(2026,4,30),"md")&" day(s)" -> 21 years, 10 month(s), 8 day(s) | J20: 38160 | K20: =DATEDIF(L20,DATE(2026,4,30),"y")&" years, "&DATEDIF(L20,DATE(2026,4,30),"ym")&" month(s), "&DATEDIF(L20,DATE(2026,4,30),"md")&" day(s)" -> 0 years, 1 month(s), 5 day(s) | L20: 46106 | O20: AISS, SMD | P20: Comp Programmer (SG6) (ISSD)
A21: 13 | B21: NUP | C21: PERM | D21: 18 | E21: AGUHO | F21: MARK ANTHONY | G21: CAMBA | I21: =DATEDIF(J21,DATE(2026,4,30),"y")&" years, "&DATEDIF(J21,DATE(2026,4,30),"ym")&" month(s), "&DATEDIF(J21,DATE(2026,4,30),"md")&" day(s)" -> 34 years, 11 month(s), 8 day(s) | J21: 33380 | K21: =DATEDIF(L21,DATE(2026,4,30),"y")&" years, "&DATEDIF(L21,DATE(2026,4,30),"ym")&" month(s), "&DATEDIF(L21,DATE(2026,4,30),"md")&" day(s)" -> 13 years, 0 month(s), 5 day(s) | L21: 41389 | O21: QAS, SMD | P21: OIC, OISS (SG18)
A22: 14 | B22: Pat | C22: PERM | D22: 376372 | E22: AGUILANDO | F22: ADAMSON | G22: BANDONG | I22: =DATEDIF(J22,DATE(2026,4,30),"y")&" years, "&DATEDIF(J22,DATE(2026,4,30),"ym")&" month(s), "&DATEDIF(J22,DATE(2026,4,30),"md")&" day(s)" -> 30 years, 10 month(s), 24 day(s) | J22: 34856 | K22: =DATEDIF(L22,DATE(2026,4,30),"y")&" years, "&DATEDIF(L22,DATE(2026,4,30),"ym")&" month(s), "&DATEDIF(L22,DATE(2026,4,30),"md")&" day(s)" -> 3 years, 4 month(s), 3 day(s) | L22: 44922 | O22: ITPMD (EOD/K9) | P22: IT Project PNCO
A23: 15 | B23: NUP | C23: PERM | D23: 7 | E23: AGUILAR | F23: BERNARDINO | G23: SANTOS | I23: =DATEDIF(J23,DATE(2026,4,30),"y")&" years, "&DATEDIF(J23,DATE(2026,4,30),"ym")&" month(s), "&DATEDIF(J23,DATE(2026,4,30),"md")&" day(s)" -> 57 years, 8 month(s), 16 day(s) | J23: 25064 | K23: =DATEDIF(L23,DATE(2026,4,30),"y")&" years, "&DATEDIF(L23,DATE(2026,4,30),"ym")&" month(s), "&DATEDIF(L23,DATE(2026,4,30),"md")&" day(s)" -> 96 years, 3 month(s), 14 day(s) | L23: 10974 | O23: ITPMD (PPDC) | P23: IT NUP (SG7)
A24: 16 | B24: PSSg | C24: PERM | D24: 260764 | E24: AGUILAR | F24: JAMES BENEDICT | G24: GALVEZ | I24: =DATEDIF(J24,DATE(2026,4,30),"y")&" years, "&DATEDIF(J24,DATE(2026,4,30),"ym")&" month(s), "&DATEDIF(J24,DATE(2026,4,30),"md")&" day(s)" -> 41 years, 8 month(s), 2 day(s) | J24: 30922 | K24: =DATEDIF(L24,DATE(2026,4,30),"y")&" years, "&DATEDIF(L24,DATE(2026,4,30),"ym")&" month(s), "&DATEDIF(L24,DATE(2026,4,30),"md")&" day(s)" -> 11 years, 4 month(s), 1 day(s) | L24: 42002 | O24: LS, ARMD | P24: RSPNCO
A25: 17 | B25: PLTCOL | C25: PERM | D25: O-22470 | E25: AGUS | F25: CARCIOLO | G25: CAJANDAB | H25: JR | I25: =DATEDIF(J25,DATE(2026,4,30),"y")&" years, "&DATEDIF(J25,DATE(2026,4,30),"ym")&" month(s), "&DATEDIF(J25,DATE(2026,4,30),"md")&" day(s)" -> 52 years, 2 month(s), 2 day(s) | J25: 27088 | K25: =DATEDIF(L25,DATE(2026,4,30),"y")&" years, "&DATEDIF(L25,DATE(2026,4,30),"ym")&" month(s), "&DATEDIF(L25,DATE(2026,4,30),"md")&" day(s)" -> 22 years, 11 month(s), 14 day(s) | L25: 37757 | O25: ITPMD (NCRPO/RICTMD NCRPO) | P25: IT Project Officer/ Asst Chief, RICTMD
A26: 18 | B26: PCPT | C26: PERM | D26: O-36666 | E26: AGUSTIN | F26: RIZELLE | G26: INALDO | I26: =DATEDIF(J26,DATE(2026,4,30),"y")&" years, "&DATEDIF(J26,DATE(2026,4,30),"ym")&" month(s), "&DATEDIF(J26,DATE(2026,4,30),"md")&" day(s)" -> 41 years, 10 month(s), 11 day(s) | J26: 30852 | K26: =DATEDIF(L26,DATE(2026,4,30),"y")&" years, "&DATEDIF(L26,DATE(2026,4,30),"ym")&" month(s), "&DATEDIF(L26,DATE(2026,4,30),"md")&" day(s)" -> 4 years, 5 month(s), 26 day(s) | L26: 44504 | M26: 38297 | O26: TSS, PTD | P26: Chief, TSS/Planning Officer
A27: 19 | B27: Pat | C27: PERM | D27: 339461 | E27: ALABA | F27: NIEL | G27: CAGAMPANG | I27: =DATEDIF(J27,DATE(2026,4,30),"y")&" years, "&DATEDIF(J27,DATE(2026,4,30),"ym")&" month(s), "&DATEDIF(J27,DATE(2026,4,30),"md")&" day(s)" -> 29 years, 6 month(s), 16 day(s) | J27: 35352 | K27: =DATEDIF(L27,DATE(2026,4,30),"y")&" years, "&DATEDIF(L27,DATE(2026,4,30),"ym")&" month(s), "&DATEDIF(L27,DATE(2026,4,30),"md")&" day(s)" -> 6 years, 6 month(s), 9 day(s) | L27: 43759 | O27: ITPMD (PRO13) | P27: IT Project PNCO
A28: 20 | B28: Pat | C28: PERM | D28: 339462 | E28: ALAWI | F28: NABIL | G28: HAJINULLA | I28: =DATEDIF(J28,DATE(2026,4,30),"y")&" years, "&DATEDIF(J28,DATE(2026,4,30),"ym")&" month(s), "&DATEDIF(J28,DATE(2026,4,30),"md")&" day(s)" -> 30 years, 7 month(s), 11 day(s) | J28: 34961 | K28: =DATEDIF(L28,DATE(2026,4,30),"y")&" years, "&DATEDIF(L28,DATE(2026,4,30),"ym")&" month(s), "&DATEDIF(L28,DATE(2026,4,30),"md")&" day(s)" -> 6 years, 6 month(s), 9 day(s) | L28: 43759 | O28: ITPMD (PRO9) | P28: IT Project PNCO
A29: 21 | B29: NUP | C29: PERM | D29: 7 | E29: ALCANTARA | F29: JHINNA-LOU | G29: SAN ESTEBAN | I29: =DATEDIF(J29,DATE(2026,4,30),"y")&" years, "&DATEDIF(J29,DATE(2026,4,30),"ym")&" month(s), "&DATEDIF(J29,DATE(2026,4,30),"md")&" day(s)" -> 28 years, 8 month(s), 21 day(s) | J29: 35651 | K29: =DATEDIF(L29,DATE(2026,4,30),"y")&" years, "&DATEDIF(L29,DATE(2026,4,30),"ym")&" month(s), "&DATEDIF(L29,DATE(2026,4,30),"md")&" day(s)" -> 3 years, 2 month(s), 16 day(s) | L29: 44971 | O29: BFS, ARMD | P29: Action NUP (SG6)
A30: 22 | B30: NUP | C30: PERM | D30: 6 | E30: ALDE | F30: MILA | G30: BERNADAS | I30: =DATEDIF(J30,DATE(2026,4,30),"y")&" years, "&DATEDIF(J30,DATE(2026,4,30),"ym")&" month(s), "&DATEDIF(J30,DATE(2026,4,30),"md")&" day(s)" -> 41 years, 7 month(s), 14 day(s) | J30: 30941 | K30: =DATEDIF(L30,DATE(2026,4,30),"y")&" years, "&DATEDIF(L30,DATE(2026,4,30),"ym")&" month(s), "&DATEDIF(L30,DATE(2026,4,30),"md")&" day(s)" -> 1 years, 1 month(s), 13 day(s) | L30: 45733 | O30: ITSD | P30: Administrative Aide VI (SG6)
